<?xml version='1.0' encoding='UTF-8'?>
<robot name="stretch">
  <link name="virtual_base_translate">
    <inertial>
      <origin xyz="0.0 0.0 0.0" rpy="0.0 -0.0 0.0"/>
      <mass value="1.0"/>
      <inertia ixx="1.0" ixy="0.0" ixz="0.0" iyy="1.0" iyz="0.0" izz="1.0"/>
    </inertial>
  </link>
  <link name="base_link">
    <inertial>
      <origin xyz="-0.087526 -0.001626 0.081009" rpy="0.0 0.0 0.0"/>
      <mass value="17.384389"/>
      <inertia ixx="0.160002" ixy="0.006758" ixz="0.004621" iyy="0.138068" iyz="0.002208" izz="0.228992"/>
    </inertial>
    <visual name="None">
      <geometry>
        <mesh filename="package://meshes/base_link.STL"/>
      </geometry>
      <material name=""/>
      <origin xyz="0.0 0.0 0.0" rpy="0.0 0.0 0.0"/>
    </visual>
    <collision name="None">
      <geometry>
        <mesh filename="package://meshes/base_link_collision.STL"/>
      </geometry>
      <origin xyz="0.0 0.0 0.0" rpy="0.0 0.0 0.0"/>
    </collision>
  </link>
  <link name="link_mast">
    <inertial>
      <origin xyz="0.000337 0.722201 0.002652" rpy="0.0 0.0 0.0"/>
      <mass value="1.764017"/>
      <inertia ixx="0.291286" ixy="0.004149" ixz="-0.000174" iyy="0.001226" iyz="0.000354" izz="0.291429"/>
    </inertial>
    <visual name="None">
      <geometry>
        <mesh filename="package://meshes/link_mast.STL"/>
      </geometry>
      <material name=""/>
      <origin xyz="0.0 0.0 0.0" rpy="0.0 0.0 0.0"/>
    </visual>
    <collision name="None">
      <geometry>
        <mesh filename="package://meshes/link_mast_collision.STL"/>
      </geometry>
      <origin xyz="0.0 0.0 0.0" rpy="0.0 0.0 0.0"/>
    </collision>
  </link>
  <link name="link_lift">
    <inertial>
      <origin xyz="-0.020369 0.03438 0.02236" rpy="0.0 0.0 0.0"/>
      <mass value="1.987167"/>
      <inertia ixx="0.006518" ixy="-0.001539" ixz="0.000371" iyy="0.004464" iyz="0.000392" izz="0.008092"/>
    </inertial>
    <visual name="None">
      <geometry>
        <mesh filename="package://meshes/link_lift.STL"/>
      </geometry>
      <material name=""/>
      <origin xyz="0.0 0.0 0.0" rpy="0.0 0.0 0.0"/>
    </visual>
    <collision name="None">
      <geometry>
        <mesh filename="package://meshes/link_lift_collision.STL"/>
      </geometry>
      <origin xyz="0.0 0.0 0.0" rpy="0.0 0.0 0.0"/>
    </collision>
  </link>
  <link name="link_arm_l4">
    <inertial>
      <origin xyz="-0.000168 -0.000254 -0.125235" rpy="0.0 0.0 0.0"/>
      <mass value="0.235626"/>
      <inertia ixx="0.001518" ixy="-1e-06" ixz="3e-06" iyy="0.001519" iyz="3e-06" izz="0.000176"/>
    </inertial>
    <visual name="None">
      <geometry>
        <mesh filename="package://meshes/link_arm_l4.STL"/>
      </geometry>
      <material name=""/>
      <origin xyz="0.0 0.0 0.0" rpy="0.0 0.0 0.0"/>
    </visual>
    <collision name="None">
      <geometry>
        <mesh filename="package://meshes/link_arm_l4_collision.STL"/>
      </geometry>
      <origin xyz="0.0 0.0 0.0" rpy="0.0 0.0 0.0"/>
    </collision>
  </link>
  <link name="link_arm_l0">
    <inertial>
      <origin xyz="0.033681 -0.000847 -0.031723" rpy="0.0 0.0 0.0"/>
      <mass value="0.427734"/>
      <inertia ixx="0.001689" ixy="-2.8e-05" ixz="0.000483" iyy="0.002107" iyz="-1.1e-05" izz="0.000571"/>
    </inertial>
    <visual name="None">
      <geometry>
        <mesh filename="package://meshes/link_arm_l0.STL"/>
      </geometry>
      <material name=""/>
      <origin xyz="0.0 0.0 0.0" rpy="0.0 0.0 0.0"/>
    </visual>
    <collision name="None">
      <geometry>
        <mesh filename="package://meshes/link_arm_l0_collision.STL"/>
      </geometry>
      <origin xyz="0.0 0.0 0.0" rpy="0.0 0.0 0.0"/>
    </collision>
  </link>
  <link name="link_wrist_yaw">
    <inertial>
      <origin xyz="0.0 -3.9e-05 -0.016495" rpy="0.0 0.0 0.0"/>
      <mass value="0.054422"/>
      <inertia ixx="9e-06" ixy="0.0" ixz="0.0" iyy="9e-06" iyz="0.0" izz="7e-06"/>
    </inertial>
    <visual name="None">
      <geometry>
        <mesh filename="package://meshes/link_wrist_yaw.STL"/>
      </geometry>
      <material name=""/>
      <origin xyz="0.0 0.0 0.0" rpy="0.0 0.0 0.0"/>
    </visual>
    <collision name="None">
      <geometry>
        <mesh filename="package://meshes/link_wrist_yaw_collision.STL"/>
      </geometry>
      <origin xyz="0.0 0.0 0.0" rpy="0.0 0.0 0.0"/>
    </collision>
  </link>
  <link name="link_wrist_yaw_bottom">
    <inertial>
      <origin xyz="-0.0165399153795968 -0.0446328107020906 -0.0281087384763343" rpy="0.0 0.0 0.0"/>
      <mass value="0.144548635554334"/>
      <inertia ixx="4.56525957614798e-05" ixy="-1.08217417869179e-06" ixz="-1.44384040297111e-08" iyy="7.22875259104698e-05" iyz="3.40820143544021e-09" izz="8.76544308203217e-05"/>
    </inertial>
    <visual name="None">
      <geometry>
        <mesh filename="package://meshes/link_DW3_wrist_yaw_bottom.STL"/>
      </geometry>
      <material name=""/>
      <origin xyz="0.0 0.0 0.0" rpy="0.0 0.0 0.0"/>
    </visual>
    <collision name="None">
      <geometry>
        <mesh filename="package://meshes/link_DW3_wrist_yaw_bottom_collision.STL"/>
      </geometry>
      <origin xyz="0.0 0.0 0.0" rpy="0.0 0.0 0.0"/>
    </collision>
  </link>
  <link name="link_wrist_pitch">
    <inertial>
      <origin xyz="-0.000711479645697954 -0.0147442681465562 0.0195140764319514" rpy="0.0 0.0 0.0"/>
      <mass value="0.116590512374845"/>
      <inertia ixx="5.76204624498191e-05" ixy="-7.78647509857216e-07" ixz="-2.86646997376633e-08" iyy="3.5844353951621e-05" iyz="1.06445058968725e-06" izz="6.36355321976534e-05"/>
    </inertial>
    <visual name="None">
      <geometry>
        <mesh filename="package://meshes/link_DW3_wrist_pitch.STL"/>
      </geometry>
      <material name=""/>
      <origin xyz="0.0 0.0 0.0" rpy="0.0 0.0 0.0"/>
    </visual>
    <collision name="None">
      <geometry>
        <mesh filename="package://meshes/link_DW3_wrist_pitch_collision.STL"/>
      </geometry>
      <origin xyz="0.0 0.0 0.0" rpy="0.0 0.0 0.0"/>
    </collision>
  </link>
  <link name="link_wrist_roll">
    <inertial>
      <origin xyz="0.000282866582415386 0.000557472767112266 0.0196635450480892" rpy="0.0 0.0 0.0"/>
      <mass value="0.0221916689638078"/>
      <inertia ixx="2.20608319376175e-06" ixy="3.01742816614342e-09" ixz="-1.83537060988685e-08" iyy="2.91436292743443e-06" iyz="-4.5509705441618e-08" izz="4.83731409646016e-06"/>
    </inertial>
    <visual name="None">
      <geometry>
        <mesh filename="package://meshes/link_DW3_wrist_roll.STL"/>
      </geometry>
      <material name=""/>
      <origin xyz="0.0 0.0 0.0" rpy="0.0 0.0 0.0"/>
    </visual>
    <collision name="None">
      <geometry>
        <mesh filename="package://meshes/link_DW3_wrist_roll_collision.STL"/>
      </geometry>
      <origin xyz="0.0 0.0 0.0" rpy="0.0 0.0 0.0"/>
    </collision>
  </link>
  <link name="link_gripper_s3_body">
    <inertial>
      <origin xyz="0.000296364207693828 0.00742489472460528 0.0440194148825503" rpy="0.0 0.0 0.0"/>
      <mass value="0.288995995074102"/>
      <inertia ixx="0.000482695285602815" ixy="-3.02029982967392e-06" ixz="6.73858128561175e-07" iyy="0.000213430693267808" iyz="-1.95797907844847e-05" izz="0.000377638305434195"/>
    </inertial>
    <visual name="None">
      <geometry>
        <mesh filename="package://meshes/link_SG3_gripper_body.STL"/>
      </geometry>
      <material name=""/>
      <origin xyz="0.0 0.0 0.0" rpy="0.0 0.0 0.0"/>
    </visual>
    <collision name="None">
      <geometry>
        <mesh filename="package://meshes/link_SG3_gripper_body_collision.STL"/>
      </geometry>
      <origin xyz="0.0 0.0 0.0" rpy="0.0 0.0 0.0"/>
    </collision>
  </link>
  <link name="link_grasp_center">
    <inertial>
      <origin xyz="0.0 0.0 0.0" rpy="0.0 -0.0 0.0"/>
      <mass value="1.0"/>
      <inertia ixx="1.0" ixy="0.0" ixz="0.0" iyy="1.0" iyz="0.0" izz="1.0"/>
    </inertial>
  </link>
  <joint name="joint_mobile_base_translation" type="prismatic">
    <limit effort="10.0" velocity="1.0" lower="-1.0" upper="1.0"/>
    <parent link="virtual_base_translate"/>
    <child link="base_link"/>
    <axis xyz="1. 0. 0."/>
    <origin xyz="0.0 0.0 0.0" rpy="0.0 -0.0 0.0"/>
  </joint>
  <joint name="joint_mast" type="fixed">
    <parent link="base_link"/>
    <child link="link_mast"/>
    <axis xyz="nan nan nan"/>
    <origin xyz="-0.06860095235643669 0.12987742365003108 0.021865940981915456" rpy="1.5759171554692506 0.008216318999469951 0.0007901691134519181"/>
  </joint>
  <joint name="joint_lift" type="prismatic">
    <limit effort="100.0" velocity="1.0" lower="0.0" upper="1.1"/>
    <parent link="link_mast"/>
    <child link="link_lift"/>
    <axis xyz="0. 0. 1."/>
    <origin xyz="-0.037385 0.1666 0.0" rpy="1.5707926535897934 1.5707926535755432 -3.141592653589793"/>
  </joint>
  <joint name="joint_arm_l4" type="fixed">
    <parent link="link_lift"/>
    <child link="link_arm_l4"/>
    <axis xyz="nan nan nan"/>
    <origin xyz="-0.2528613884035527 -0.003758153613036904 -0.0043824465179106206" rpy="1.567364813311696 0.0021888523469442145 -1.544169014753703"/>
  </joint>
  <joint name="joint_arm_l0" type="prismatic">
    <limit effort="100.0" velocity="1.0" lower="0.0" upper="0.52"/>
    <parent link="link_arm_l4"/>
    <child link="link_arm_l0"/>
    <axis xyz="0. 0. 1."/>
    <origin xyz="0.0 0.0 0.025250000000801298" rpy="7.63746778746202e-30 -3.80121128864402e-15 2.62707547767438e-15"/>
  </joint>
  <joint name="joint_wrist_yaw" type="revolute">
    <limit effort="100.0" velocity="1.0" lower="-1.75" upper="4.0"/>
    <parent link="link_arm_l0"/>
    <child link="link_wrist_yaw"/>
    <axis xyz=" 0.  0. -1."/>
    <origin xyz="0.0830000000000654 -0.0307500000000129 0.0" rpy="-1.5707963267949 0.0 3.14159265358978"/>
  </joint>
  <joint name="joint_wrist_yaw_bottom" type="fixed">
    <parent link="link_wrist_yaw"/>
    <child link="link_wrist_yaw_bottom"/>
    <axis xyz="nan nan nan"/>
    <origin xyz="0.0 0.0 0.0" rpy="-3.14159265358979 0.0 -1.5707963267949"/>
  </joint>
  <joint name="joint_wrist_pitch" type="revolute">
    <limit effort="100.0" velocity="1.0" lower="-1.57" upper="0.56"/>
    <parent link="link_wrist_yaw_bottom"/>
    <child link="link_wrist_pitch"/>
    <axis xyz=" 0.  0. -1."/>
    <origin xyz="0.0 -0.019455 -0.0305" rpy="1.5708 0.0 -3.1415853071795867"/>
  </joint>
  <joint name="joint_wrist_roll" type="revolute">
    <limit effort="100.0" velocity="1.0" lower="-3.14" upper="3.14"/>
    <parent link="link_wrist_pitch"/>
    <child link="link_wrist_roll"/>
    <axis xyz="0. 0. 1."/>
    <origin xyz="-0.018859 -0.024 0.01955" rpy="7.3464102067096675e-06 1.5707926535755432 -3.141592653589793"/>
  </joint>
  <joint name="joint_gripper_s3_body" type="fixed">
    <parent link="link_wrist_roll"/>
    <child link="link_gripper_s3_body"/>
    <axis xyz="nan nan nan"/>
    <origin xyz="0.0 0.0 0.0209999999993159" rpy="0.0 0.0 -3.14159265358975"/>
  </joint>
  <joint name="joint_grasp_center" type="fixed">
    <parent link="link_gripper_s3_body"/>
    <child link="link_grasp_center"/>
    <axis xyz="1. 0. 0."/>
    <origin xyz="0.0 0.0 0.23" rpy="-1.5707963267949 -1.5707963267948966 0.0"/>
  </joint>
  <link name="link_shaver">
    <inertial>
      <origin xyz="0.0 0.0 0.0" rpy="0.0 -0.0 0.0"/>
      <mass value="0.0"/>
      <inertia ixx="0.0" ixy="0.0" ixz="0.0" iyy="0.0" iyz="0.0" izz="0.0"/>
    </inertial>
  </link>
  <joint name="joint_shaver" type="fixed">
    <parent link="link_grasp_center"/>
    <child link="link_shaver"/>
    <axis xyz="nan nan nan"/>
    <origin xyz="0.05 0.0 0.035" rpy="0.0 0.5 0.0"/>
  </joint>
  <material name="aluminum">
    <color rgba="0.5 0.5 0.5 1. "/>
  </material>
  <material name="plastic">
    <color rgba="0.1 0.1 0.1 1. "/>
  </material>
  <material name="">
    <color rgba="0.79216 0.81961 0.93333 1.     "/>
  </material>
</robot>